Workbook

Sheet AvanceJGA
A1: #VALUE! | B1: Avances generales de Obra
A2: Sistema | B2: DISCIPLINA | C2: Area/Sector | D2: Tarea | E2: Cantidad Objetivo | F2: Unidad de Medida | G2: Ejecutado | H2: Pendiente | I2: Avance(%)
A3: Parque de Almacenamiento | B3: Civil | C3: Power Block N° 1 | D3: Fundaciones Baterías (BESS) | E3: 6 | F3: Unidad | G3: 6 | H3: =E3-G3 -> 0 | I3: =IFERROR(G3/E3,"-") -> 1
A4: Parque de Almacenamiento | B4: Civil | C4: Power Block N° 1 | D4: Fundaciones PCS(Power Conversion Systems) | E4: 48 | F4: Unidad | G4: 48 | H4: =E4-G4 -> 0 | I4: =IFERROR(G4/E4,"-") -> 1
A5: Parque de Almacenamiento | B5: Civil | C5: Power Block N° 1 | D5: Fundaciones STS (Centro de Transfomacion) | E5: 1 | F5: Unidad | G5: 1 | H5: =E5-G5 -> 0 | I5: =IFERROR(G5/E5,"-") -> 1
A6: Parque de Almacenamiento | B6: Civil | C6: Power Block N° 1 | D6: Fundacion Tablero Seccional | E6: 1 | F6: Unidad | G6: 0 | H6: =E6-G6 -> 1 | I6: =IFERROR(G6/E6,"-") -> 0
A7: Parque de Almacenamiento | B7: Electromecanico | C7: Power Block N° 1 | D7: Montaje BESS | E7: 6 | F7: Unidad | G7: 6 | H7: =E7-G7 -> 0 | I7: =IFERROR(G7/E7,"-") -> 1
A8: Parque de Almacenamiento | B8: Electromecanico | C8: Power Block N° 1 | D8: Montaje PCS | E8: 48 | F8: Unidad | G8: 48 | H8: =E8-G8 -> 0 | I8: =IFERROR(G8/E8,"-") -> 1
A9: Parque de Almacenamiento | B9: Electromecanico | C9: Power Block N° 1 | D9: Montaje STS | E9: 1 | F9: Unidad | G9: 1 | H9: =E9-G9 -> 0 | I9: =IFERROR(G9/E9,"-") -> 1
A10: Parque de Almacenamiento | B10: Electromecanico | C10: Power Block N° 1 | D10: Armado puntas DC | E10: 192 | F10: Unidad | G10: 192 | H10: =E10-G10 -> 0 | I10: =IFERROR(G10/E10,"-") -> 1
A11: Parque de Almacenamiento | B11: Electromecanico | C11: Power Block N° 1 | D11: Armado puntas AC | E11: 288 | F11: Unidad | G11: 288 | H11: =E11-G11 -> 0 | I11: =IFERROR(G11/E11,"-") -> 1
A12: Parque de Almacenamiento | B12: Electromecanico | C12: Power Block N° 1 | D12: Montaje de tablero Seccional | E12: 1 | F12: Unidad | G12: 0 | H12: =E12-G12 -> 1 | I12: =IFERROR(G12/E12,"-") -> 0
A13: Parque de Almacenamiento | B13: Civil | C13: Power Block N° 2 | D13: Fundaciones Baterías (BESS) | E13: 6 | F13: Unidad | G13: 6 | H13: =E13-G13 -> 0 | I13: =IFERROR(G13/E13,"-") -> 1
A14: Parque de Almacenamiento | B14: Civil | C14: Power Block N° 2 | D14: Fundaciones PCS(Power Conversion Systems) | E14: 48 | F14: Unidad | G14: 48 | H14: =E14-G14 -> 0 | I14: =IFERROR(G14/E14,"-") -> 1
... A20: Parque de Almacenamiento | B20: Electromecanico | C20: Power Block N° 2 | D20: Armado puntas DC | E20: 192 | F20: Unidad | G20: 192 | H20: =E20-G20 -> 0 | I20: =IFERROR(G20/E20,"-") -> 1
A21: Parque de Almacenamiento | B21: Electromecanico | C21: Power Block N° 2 | D21: Armado puntas AC | E21: 288 | F21: Unidad | G21: 288 | H21: 144 | I21: =IFERROR(G21/E21,"-") -> 1
A22: Parque de Almacenamiento | B22: Electromecanico | C22: Power Block N° 2 | D22: Montaje de tablero Seccional | E22: 1 | F22: Unidad | G22: 0 | H22: =E22-G22 -> 1 | I22: =IFERROR(G22/E22,"-") -> 0
A23: Parque de Almacenamiento | B23: Civil | C23: Power Block N° 3 | D23: Fundaciones Baterías (BESS) | E23: 6 | F23: Unidad | G23: 6 | H23: =E23-G23 -> 0 | I23: =IFERROR(G23/E23,"-") -> 1
A24: Parque de Almacenamiento | B24: Civil | C24: Power Block N° 3 | D24: Fundaciones PCS(Power Conversion Systems) | E24: 48 | F24: Unidad | G24: 48 | H24: =E24-G24 -> 0 | I24: =IFERROR(G24/E24,"-") -> 1
A25: Parque de Almacenamiento | B25: Civil | C25: Power Block N° 3 | D25: Fundaciones STS (Centro de Transfomacion) | E25: 1 | F25: Unidad | G25: 1 | H25: =E25-G25 -> 0 | I25: =IFERROR(G25/E25,"-") -> 1
A26: Parque de Almacenamiento | B26: Civil | C26: Power Block N° 3 | D26: Fundacion Tablero Seccional | E26: 1 | F26: Unidad | G26: 0 | H26: =E26-G26 -> 1 | I26: =IFERROR(G26/E26,"-") -> 0
A27: Parque de Almacenamiento | B27: Electromecanico | C27: Power Block N° 3 | D27: Montaje BESS | E27: 6 | F27: Unidad | G27: 6 | H27: =E27-G27 -> 0 | I27: =IFERROR(G27/E27,"-") -> 1
A28: Parque de Almacenamiento | B28: Electromecanico | C28: Power Block N° 3 | D28: Montaje PCS | E28: 48 | F28: Unidad | G28: 48 | H28: =E28-G28 -> 0 | I28: =IFERROR(G28/E28,"-") -> 1
A29: Parque de Almacenamiento | B29: Electromecanico | C29: Power Block N° 3 | D29: Montaje STS | E29: 1 | F29: Unidad | G29: 1 | H29: =E29-G29 -> 0 | I29: =IFERROR(G29/E29,"-") -> 1
A30: Parque de Almacenamiento | B30: Electromecanico | C30: Power Block N° 3 | D30: Armado puntas DC | E30: 192 | F30: Unidad | G30: 192 | H30: =E30-G30 -> 0 | I30: =IFERROR(G30/E30,"-") -> 1
A31: Parque de Almacenamiento | B31: Electromecanico | C31: Power Block N° 3 | D31: Armado puntas AC | E31: 288 | F31: Unidad | G31: 288 | H31: =E31-G31 -> 0 | I31: =IFERROR(G31/E31,"-") -> 1
A32: Parque de Almacenamiento | B32: Electromecanico | C32: Power Block N° 3 | D32: Montaje de tablero Seccional | E32: 1 | F32: Unidad | G32: 0 | H32: =E32-G32 -> 1 | I32: =IFERROR(G32/E32,"-") -> 0
A33: Parque de Almacenamiento | B33: Civil | C33: Power Block N° 4 | D33: Fundaciones Baterías (BESS) | E33: 6 | F33: Unidad | G33: 6 | H33: =E33-G33 -> 0 | I33: =IFERROR(G33/E33,"-") -> 1
... A230: Parque de Almacenamiento | B230: Electromecanico | C230: Power Block N° 23 | D230: Armado puntas DC | E230: 192 | F230: Unidad | G230: 192 | H230: =E230-G230 -> 0 | I230: =IFERROR(G230/E230,"-") -> 1
A231: Parque de Almacenamiento | B231: Electromecanico | C231: Power Block N° 23 | D231: Armado puntas AC | E231: 288 | F231: Unidad | G231: 288 | H231: 288 | I231: =IFERROR(G231/E231,"-") -> 1
A232: Parque de Almacenamiento | B232: Electromecanico | C232: Power Block N° 23 | D232: Montaje de tablero Seccional | E232: 1 | F232: Unidad | G232: 0 | H232: =E232-G232 -> 1 | I232: =IFERROR(G232/E232,"-") -> 0
A233: Interconexión: Obra Interconexión MT-AT | B233: Civil | C233: Estacion Transformadora(ET) | D233: Fundaciones para Transformador principal | E233: 2 | F233: Unidad | G233: 2 | H233: =E233-G233 -> 0 | I233: =IFERROR(G233/E233,"-") -> 1
A234: Interconexión: Obra Interconexión MT-AT | B234: Civil | C234: Estacion Transformadora(ET) | D234: Fundacion Interruptores | E234: 3 | F234: Unidad | G234: 3 | H234: =E234-G234 -> 0 | I234: =IFERROR(G234/E234,"-") -> 1
A235: Interconexión: Obra Interconexión MT-AT | B235: Civil | C235: Estacion Transformadora(ET) | D235: Fundacion Seccionadores | E235: 2 | F235: Unidad | G235: 2 | H235: =E235-G235 -> 0 | I235: =IFERROR(G235/E235,"-") -> 1
A236: Interconexión: Obra Interconexión MT-AT | B236: Civil | C236: Estacion Transformadora(ET) | D236: Fundacion Reactancia de Neutros | E236: 2 | F236: Unidad | G236: 2 | H236: =E236-G236 -> 0 | I236: =IFERROR(G236/E236,"-") -> 1
A237: Interconexión: Obra Interconexión MT-AT | B237: Civil | C237: Estacion Transformadora(ET) | D237: Fundaciones para postes de Iluminacion | E237: 4 | F237: Unidad | G237: 4 | H237: =E237-G237 -> 0 | I237: =IFERROR(G237/E237,"-") -> 1
A238: Interconexión: Obra Interconexión MT-AT | B238: Civil | C238: Estacion Transformadora(ET) | D238: Fundacion para porticos de Barra | E238: 4 | F238: Unidad | G238: 4 | H238: =E238-G238 -> 0 | I238: =IFERROR(G238/E238,"-") -> 1
A239: Interconexión: Obra Interconexión MT-AT | B239: Civil | C239: Estacion Transformadora(ET) | D239: Fundaciones para TI | E239: 6 | F239: Unidad | G239: 6 | H239: =E239-G239 -> 0 | I239: =IFERROR(G239/E239,"-") -> 1
A240: Interconexión: Obra Interconexión MT-AT | B240: Civil | C240: Estacion Transformadora(ET) | D240: Fundaciones para TV | E240: 3 | F240: Unidad | G240: 3 | H240: =E240-G240 -> 0 | I240: =IFERROR(G240/E240,"-") -> 1
A241: Interconexión: Obra Interconexión MT-AT | B241: Electromecanico | C241: Estacion Transformadora(ET) | D241: Montaje de interruptores | E241: 2 | F241: Unidad | G241: 2 | H241: =E241-G241 -> 0 | I241: =IFERROR(G241/E241,"-") -> 1
...

Sheet PUNTAS MT
A1: Descripcion de Tarea | B1: Power Block | C1: Objetivo | D1: Formacion | E1: Ejecutado | F1: Restante | G1: Avance
A2: Armado de Puntas | B2: Power Block N°1 | C2: 3 | D2: 1x(3x1x185) | E2: 0 | F2: ='PUNTAS MT'!$C2-'PUNTAS MT'!$E2 -> 3 | G2: ='PUNTAS MT'!$E2/'PUNTAS MT'!$C2 -> 0
A3: Armado de Puntas | B3: Power Block N°2 | C3: 6 | D3: 2x(3x1x400) | E3: 0 | F3: ='PUNTAS MT'!$C3-'PUNTAS MT'!$E3 -> 6 | G3: ='PUNTAS MT'!$E3/'PUNTAS MT'!$C3 -> 0
A4: Armado de Puntas | B4: Power Block N°2 | C4: 3 | D4: 1x(3x1x500) | E4: 0 | F4: ='PUNTAS MT'!$C4-'PUNTAS MT'!$E4 -> 3 | G4: ='PUNTAS MT'!$E4/'PUNTAS MT'!$C4 -> 0
A5: Armado de Puntas | B5: Power Block N°3 | C5: 3 | D5: 1x(3x1x185) | E5: 3 | F5: ='PUNTAS MT'!$C5-'PUNTAS MT'!$E5 -> 0 | G5: ='PUNTAS MT'!$E5/'PUNTAS MT'!$C5 -> 1
A6: Armado de Puntas | B6: Power Block N°3 | C6: 3 | D6: 1x(3x1x500) | E6: 3 | F6: ='PUNTAS MT'!$C6-'PUNTAS MT'!$E6 -> 0 | G6: ='PUNTAS MT'!$E6/'PUNTAS MT'!$C6 -> 1
A7: Armado de Puntas | B7: Power Block N°4 | C7: 3 | D7: 1x(3x1x185) | E7: 3 | F7: ='PUNTAS MT'!$C7-'PUNTAS MT'!$E7 -> 0 | G7: ='PUNTAS MT'!$E7/'PUNTAS MT'!$C7 -> 1
A8: Armado de Puntas | B8: Power Block N°5 | C8: 6 | D8: 2x(3x1x400) | E8: 6 | F8: ='PUNTAS MT'!$C8-'PUNTAS MT'!$E8 -> 0 | G8: ='PUNTAS MT'!$E8/'PUNTAS MT'!$C8 -> 1
A9: Armado de Puntas | B9: Power Block N°5 | C9: 3 | D9: 1x(3x1x500) | E9: 3 | F9: ='PUNTAS MT'!$C9-'PUNTAS MT'!$E9 -> 0 | G9: ='PUNTAS MT'!$E9/'PUNTAS MT'!$C9 -> 1
A10: Armado de Puntas | B10: Power Block N°6 | C10: 3 | D10: 1x(3x1x185) | E10: 3 | F10: ='PUNTAS MT'!$C10-'PUNTAS MT'!$E10 -> 0 | G10: ='PUNTAS MT'!$E10/'PUNTAS MT'!$C10 -> 1
A11: Armado de Puntas | B11: Power Block N°6 | C11: 3 | D11: 1x(3x1x500) | E11: 3 | F11: ='PUNTAS MT'!$C11-'PUNTAS MT'!$E11 -> 0 | G11: ='PUNTAS MT'!$E11/'PUNTAS MT'!$C11 -> 1
A12: Armado de Puntas | B12: Power Block N°7 | C12: 3 | D12: 1x(3x1x185) | E12: 3 | F12: ='PUNTAS MT'!$C12-'PUNTAS MT'!$E12 -> 0 | G12: ='PUNTAS MT'!$E12/'PUNTAS MT'!$C12 -> 1
A13: Armado de Puntas | B13: Power Block N°8 | C13: 6 | D13: 2x(3x1x400) | E13: 6 | F13: ='PUNTAS MT'!$C13-'PUNTAS MT'!$E13 -> 0 | G13: ='PUNTAS MT'!$E13/'PUNTAS MT'!$C13 -> 1
... A53: Armado de Puntas | B53: TRSA-05 | C53: 3 | D53: 1x(3x1x185) | E53: 0 | F53: ='PUNTAS MT'!$C53-'PUNTAS MT'!$E53 -> 3 | G53: ='PUNTAS MT'!$E53/'PUNTAS MT'!$C53 -> 0
C54: =SUM(C2:C53) -> 198 | E54: =SUM(E2:E53) -> 99 | F54: =SUM(F2:F53) -> 99 | G54: ='PUNTAS MT'!$E$54/'PUNTAS MT'!$C$54 -> 0.5

Sheet Datos_BESS-Nuevo Puerto
A2: #VALUE! | C2: Seguimiento de cantidades Instaladas en Obra - Nuevo Puerto
A3: Proyecto | B3: Área / Subsistema | C3: Ítem / Equipo | D3: Unidad de Medida | E3: Cantidad Planificada | F3: Cantidad Instalada | G3: Cantidad Pendiente | H3: Porcentaje Avance | I3: Estado de Avance | J3: Observaciones / Comentarios
A4: Central Puerto | B4: CMM | C4: Construccion de Edificios de Celdas MT | D4: GL | E4: 1 | F4: 0.4 | G4: =E4-F4 -> 0.6 | H4: =F4/E4 -> 0.4 | I4: =IF(H4=1,"Completado",IF(H4>0,"En Proceso","Pendiente")) -> En Proceso
A5: Central Puerto | B5: Fundaciones Civil | C5: Bases de Concreto Baterías (CATL) | D5: Unidad | E5: 153 | F5: 153 | G5: =E5-F5 -> 0 | H5: =F5/E5 -> 1 | I5: =IF(H5=1,"Completado",IF(H5>0,"En Proceso","Pendiente")) -> Completado
A6: Central Puerto | B6: Fundaciones Civil | C6: Bases para PCS(Power Conversion Systems) | D6: Unidad | E6: 1080 | F6: 1080 | G6: =E6-F6 -> 0 | H6: =F6/E6 -> 1 | I6: =IF(H6=1,"Completado",IF(H6>0,"En Proceso","Pendiente")) -> Completado
A7: Central Puerto | B7: Fundaciones Civil | C7: Bases para STS (Centro de Transfomacion) | D7: Unidad | E7: 23 | F7: 23 | G7: =E7-F7 -> 0 | H7: =F7/E7 -> 1 | I7: =IF(H7=1,"Completado",IF(H7>0,"En Proceso","Pendiente")) -> Completado
A8: Central Puerto | B8: Fundaciones Civil | C8: Bases para Transformadores Principales. | D8: Unidad | E8: 2 | F8: 2 | G8: =E8-F8 -> 0 | H8: =F8/E8 -> 1 | I8: =IF(H8=1,"Completado",IF(H8>0,"En Proceso","Pendiente")) -> Completado
A9: Central Puerto | B9: Fundaciones Civil | C9: Fundaciones de Transformadores SSAA. | D9: Unidad | E9: 5 | F9: 4 | G9: =E9-F9 -> 1 | H9: =F9/E9 -> 0.8 | I9: =IF(H9=1,"Completado",IF(H9>0,"En Proceso","Pendiente")) -> En Proceso
A10: Central Puerto | B10: Fundaciones Civil | C10: Fundaciones de Tablero SSAA. | D10: Unidad | E10: 5 | F10: 0 | G10: =E10-F10 -> 5 | H10: =F10/E10 -> 0 | I10: =IF(H10=1,"Completado",IF(H10>0,"En Proceso","Pendiente")) -> Pendiente
A11: Central Puerto | B11: Fundaciones Civil | C11: Fundaciones de Tableros Seccionales | D11: Unidad | E11: 23 | F11: 0 | G11: =E11-F11 -> 23 | H11: =F11/E11 -> 0 | I11: =IF(H11=1,"Completado",IF(H11>0,"En Proceso","Pendiente")) -> Pendiente
A12: Central Puerto | B12: Fundaciones Civil | C12: Fundacion de Grupos Electrogenos(Generadores) | D12: Unidad | E12: 4 | F12: 0 | G12: =E12-F12 -> 4 | H12: =F12/E12 -> 0 | I12: =IF(H12=1,"Completado",IF(H12>0,"En Proceso","Pendiente")) -> Pendiente
A13: Central Puerto | B13: Fundaciones Civil | C13: Bases para postes de iluminacion de Estacion Transformadora | D13: Unidad | E13: 4 | F13: 4 | G13: =E13-F13 -> 0 | H13: =F13/E13 -> 1 | I13: =IF(H13=1,"Completado",IF(H13>0,"En Proceso","Pendiente")) -> Completado
A14: Central Puerto | B14: Fundaciones Civil | C14: Bases para seccionadores | D14: Unidad | E14: 3 | F14: 3 | G14: =E14-F14 -> 0 | H14: =F14/E14 -> 1 | I14: =IF(H14=1,"Completado",IF(H14>0,"En Proceso","Pendiente")) -> Completado
A15: Central Puerto | B15: Fundaciones Civil | C15: Bases para Interruptores | D15: Unidad | E15: 2 | F15: 2 | G15: =E15-F15 -> 0 | H15: =F15/E15 -> 1 | I15: =IF(H15=1,"Completado",IF(H15>0,"En Proceso","Pendiente")) -> Completado
A16: Central Puerto | B16: Fundaciones Civil | C16: Bases para Iluminacion perimetral | D16: Unidad | E16: 50 | F16: 20 | G16: =E16-F16 -> 30 | H16: =F16/E16 -> 0.4 | I16: =IF(H16=1,"Completado",IF(H16>0,"En Proceso","Pendiente")) -> En Proceso | J16: a confirmar
A17: Central Puerto | B17: Fundaciones Civil | C17: Bases para reactancia de Neutros | D17: Unidad | E17: 2 | F17: 2 | G17: =E17-F17 -> 0 | H17: =F17/E17 -> 1 | I17: =IF(H17=1,"Completado",IF(H17>0,"En Proceso","Pendiente")) -> Completado
A18: Central Puerto | B18: Montaje de equipos | C18: Contenedores de Baterías BESS (BESS) | D18: Unidad | E18: 153 | F18: 153 | G18: =E18-F18 -> 0 | H18: =F18/E18 -> 1 | I18: =IF(H18=1,"Completado",IF(H18>0,"En Proceso","Pendiente")) -> Completado
A19: Central Puerto | B19: Montaje de equipos | C19: Transformadores Principales de Potencia | D19: Unidad | E19: 2 | F19: 0 | G19: =E19-F19 -> 2 | H19: =F19/E19 -> 0 | I19: =IF(H19=1,"Completado",IF(H19>0,"En Proceso","Pendiente")) -> Pendiente
A20: Central Puerto | B20: Montaje de equipos | C20: Inversores / PCS (Power Conversion System) | D20: Unidad | E20: 1080 | F20: 648 | G20: =E20-F20 -> 432 | H20: =F20/E20 -> 0.6 | I20: =IF(H20=1,"Completado",IF(H20>0,"En Proceso","Pendiente")) -> En Proceso
A21: Central Puerto | B21: Montaje de equipos | C21: Centro de Transformacion (STS) | D21: Unidad | E21: 23 | F21: 23 | G21: =E21-F21 -> 0 | H21: =F21/E21 -> 1 | I21: =IF(H21=1,"Completado",IF(H21>0,"En Proceso","Pendiente")) -> Completado
A22: Central Puerto | B22: Montaje de equipos | C22: Transformadores SSAA | D22: Unidad | E22: 5 | F22: 5 | G22: =E22-F22 -> 0 | H22: =F22/E22 -> 1 | I22: =IF(H22=1,"Completado",IF(H22>0,"En Proceso","Pendiente")) -> Completado
A23: Central Puerto | B23: Montaje de equipos | C23: Tableros SSAA | D23: Unidad | E23: 5 | F23: 0 | G23: =E23-F23 -> 5 | H23: =F23/E23 -> 0 | I23: =IF(H23=1,"Completado",IF(H23>0,"En Proceso","Pendiente")) -> Pendiente
A24: Central Puerto | B24: Montaje de equipos | C24: Tableros Seccionales | D24: Unidad | E24: 23 | F24: 0 | G24: =E24-F24 -> 23 | H24: =F24/E24 -> 0 | I24: =IF(H24=1,"Completado",IF(H24>0,"En Proceso","Pendiente")) -> Pendiente
A25: Central Puerto | B25: Montaje de equipos | C25: Grupos Electrogenos(Generadores) | D25: Unidad | E25: 4 | F25: 0 | G25: =E25-F25 -> 4 | H25: =F25/E25 -> 0 | I25: =IF(H25=1,"Completado",IF(H25>0,"En Proceso","Pendiente")) -> Pendiente
A26: Central Puerto | B26: Conexionado | C26: Conexiones en PCS—BESS(estimado). | D26: Unidad | E26: 2160 | F26: 820 | G26: =E26-F26 -> 1340 | H26: =F26/E26 -> 0.37962963 | I26: =IF(H26=1,"Completado",IF(H26>0,"En Proceso","Pendiente")) -> En Proceso | J26: Sin torqueo
A27: Central Puerto | B27: Conexionado | C27: Conexiones-PCS—STS(estimado). | D27: Unidad | E27: 3240 | F27: 1200 | G27: =E27-F27 -> 2040 | H27: =F27/E27 -> 0.37037037 | I27: =IF(H27=1,"Completado",IF(H27>0,"En Proceso","Pendiente")) -> En Proceso | J27: Sin torqueo

Sheet Datos_BESS-Central Costanera
A2: #VALUE! | C2: Estado de avance de Equipos Central Costanera
A3: Proyecto | B3: Área / Subsistema | C3: Ítem / Equipo | D3: Unidad de Medida | E3: Cantidad Planificada | F3: Cantidad Instalada | G3: Cantidad Pendiente | H3: Porcentaje Avance | I3: Estado de Avance | J3: Observaciones / Comentarios
A4: Central Costanera | B4: CMM | C4: Construccion de Edificios de Celdas MT | D4: GL | E4: 1 | F4: 1 | G4: =E4-F4 -> 0 | H4: =F4/E4 -> 1 | I4: =IF(H4=1,"Completado",IF(H4>0,"En Proceso","Pendiente")) -> Completado
A5: Central Costanera | B5: Fundaciones Civil | C5: Bases de Concreto Baterías (CATL) | D5: Unidad | E5: 50 | F5: 50 | G5: =E5-F5 -> 0 | H5: =IFERROR(F5/E5,"") -> 1 | I5: =IF(H5=1,"Completado",IF(H5>0,"En Proceso","Pendiente")) -> Completado
A6: Central Costanera | B6: Fundaciones Civil | C6: Bases para PCS(Power Conversion Systems) | D6: Unidad | E6: 400 | F6: 300 | G6: =E6-F6 -> 100 | H6: =IFERROR(F6/E6,"") -> 0.75 | I6: =IF(H6=1,"Completado",IF(H6>0,"En Proceso","Pendiente")) -> En Proceso
A7: Central Costanera | B7: Fundaciones Civil | C7: Bases para STS (Centro de Transfomacion) | D7: Unidad | E7: 9 | F7: 9 | G7: =E7-F7 -> 0 | H7: =IFERROR(F7/E7,"") -> 1 | I7: =IF(H7=1,"Completado",IF(H7>0,"En Proceso","Pendiente")) -> Completado
A8: Central Costanera | B8: Fundaciones Civil | C8: Bases para Transformadores Principales. | D8: Unidad | E8: 1 | F8: 0 | G8: =E8-F8 -> 1 | H8: =IFERROR(F8/E8,"") -> 0 | I8: =IF(H8=1,"Completado",IF(H8>0,"En Proceso","Pendiente")) -> Pendiente
A9: Central Costanera | B9: Fundaciones Civil | C9: Fundaciones de Transformadores SSAA. | D9: Unidad | E9: 2 | F9: 2 | G9: =E9-F9 -> 0 | H9: =IFERROR(F9/E9,"") -> 1 | I9: =IF(H9=1,"Completado",IF(H9>0,"En Proceso","Pendiente")) -> Completado
A10: Central Costanera | B10: Fundaciones Civil | C10: Fundaciones de Grupos Electrogenos(Generadores) | D10: Unidad | E10: 2 | F10: 2 | G10: =E10-F10 -> 0 | H10: =IFERROR(F10/E10,"") -> 1 | I10: =IF(H10=1,"Completado",IF(H10>0,"En Proceso","Pendiente")) -> Completado
A11: Central Costanera | B11: Fundaciones Civil | C11: Fundación cámaras CA-STS | D11: Unidad | E11: 10 | F11: 10 | G11: =E11-F11 -> 0 | H11: =IFERROR(F11/E11,"") -> 1 | I11: =IF(H11=1,"Completado",IF(H11>0,"En Proceso","Pendiente")) -> Completado
A12: Central Costanera | B12: Fundaciones Civil | C12: Fundación cámaras CA-SSAA | D12: Unidad | E12: 2 | F12: 2 | G12: =E12-F12 -> 0 | H12: =IFERROR(F12/E12,"") -> 1 | I12: =IF(H12=1,"Completado",IF(H12>0,"En Proceso","Pendiente")) -> Completado
A13: Central Costanera | B13: Fundaciones Civil | C13: Fundación cámaras CP-CMM | D13: Unidad | E13: 2 | F13: 2 | G13: =E13-F13 -> 0 | H13: =IFERROR(F13/E13,"") -> 1 | I13: =IF(H13=1,"Completado",IF(H13>0,"En Proceso","Pendiente")) -> Completado
A14: Central Costanera | B14: Fundaciones Civil | C14: Cerco Olímpico Perimetral | D14: Ml | E14: 430 | F14: 0 | G14: =E14-F14 -> 430 | H14: =IFERROR(F14/E14,"") -> 0 | I14: =IF(H14=1,"Completado",IF(H14>0,"En Proceso","Pendiente")) -> Pendiente
A15: Central Costanera | B15: Fundaciones Civil | C15: Fundación Postes de Iluminación | D15: Unidad | E15: 30 | F15: 6 | G15: =E15-F15 -> 24 | H15: =IFERROR(F15/E15,"") -> 0.2 | I15: =IF(H15=1,"Completado",IF(H15>0,"En Proceso","Pendiente")) -> En Proceso
A16: Central Costanera | B16: Fundaciones Civil | C16: Construcción de Sala de Protecciones | D16: Unidad | E16: 1 | F16: 0.5 | G16: =E16-F16 -> 0.5 | H16: =IFERROR(F16/E16,"") -> 0.5 | I16: =IF(H16=1,"Completado",IF(H16>0,"En Proceso","Pendiente")) -> En Proceso
... A23: Central Costanera | B23: Montaje de equipos | C23: Transformadores SSAA | D23: Unidad | E23: 2 | F23: 2 | G23: =E23-F23 -> 0 | H23: =IFERROR(F23/E23,"") -> 1 | I23: =IF(H23=1,"Completado",IF(H23>0,"En Proceso","Pendiente")) -> Completado
A24: Central Costanera | B24: Montaje de equipos | C24: Grupos Electrogenos(Generadores) | D24: Unidad | E24: 2 | F24: 2 | G24: =E24-F24 -> 0 | H24: =F24/E24 -> 1 | I24: =IF(H24=1,"Completado",IF(H24>0,"En Proceso","Pendiente")) -> Completado
